File: Data sample/B-Carotene/CM-200113-bCarotene.txt
#Acq. time (s)=	1
#Accumulations=	5
#Range=	Off
#Autofocus=	Off
#AutoExposure=	Off
#Spike filter=	Multiple accum.
#Delay time (s)=	0
#Binning=	1
#Readout mode=	Signal
#DeNoise=	Off
#ICS correction=	Off
#Dark correction=	Off
#Inst. Process=	Off
#Detector temperature (°C)=	-70.24
#Instrument=	LabRAM
#Detector=	Synapse
#Objective=	x10 MPlan
#Grating (mm)=	300 gr
#Filter=	1%
#Laser (nm)=	532
#Spectro (cm-¹)=	1850
#Slit=	200
#Hole=	525
#StageXY=	Marzhauser
#X (µm)=	0
#Y (µm)=	0
#Full time(s)=	6
#Project=	Pigments
#Sample=	b-Carotene
#Site=
#Title=	b-Carotene_1
#Remark=
#Date=	13.01.2020 11:02
#Acquired=	13.01.2020 11:02:34
3278.74	13912
3276.18	13752
3273.61	13909.8
3271.05	13936.5
3268.49	13743
3265.92	13753.5
3263.36	14007.5
3260.79	13808.3
3258.22	13681
3255.66	13963
3253.09	13890.8
3250.52	13769
3247.95	13967.8
3245.38	14080
3242.8	13910.3
3240.23	13994.3
3237.66	14186.5
3235.08	14023.5
3232.51	13921.8
3229.93	14128.3
3227.35	14302.8
3224.77	13998.8
3222.19	14313.5
3219.61	14386.5
3217.03	14251.5
3214.45	14255.8
3211.87	14562
3209.28	14581.3
3206.7	14455.5
3204.12	14623
3201.53	14723.5
3198.94	14768
3196.35	14643.5
3193.77	14961
3191.18	15122.5
3188.58	14883.3
3185.99	15126.5
3183.4	15245
3180.81	15088.8
3178.21	15171.5
3175.62	15475
3173.02	15544.8
3170.43	15418
3167.83	15446.5
3165.23	15797.3
3162.63	15616.3
3160.03	15571.5
3157.43	15881.5
3154.83	15762.3
3152.22	15728.3
3149.62	15731.3
3147.01	15982.8
3144.41	15733.3
3141.8	15807.3
3139.2	15947.8
3136.59	15911.5
3133.98	15741.8
3131.37	15915.3
3128.76	15962
3126.14	15803.8
3123.53	15713.5
3120.92	16039.3
3118.3	15911.3
3115.69	15680
3113.07	15791
3110.45	15994.8
3107.84	15838.5
3105.22	15737.5
3102.6	16083.8
3099.98	16054
3097.36	15761.8
3094.73	15877.5
3092.11	16060.8
3089.48	16007.3
3086.86	15871
3084.23	16103.8
3081.61	16084.8
3078.98	15877.3
3076.35	16002.8
3073.72	16167.5
3071.09	15982.8
3068.46	15903.3
3065.82	16127.3
3063.19	16310
3060.56	16141
3057.92	16239.8
3055.29	16494
3052.65	16456.3
3050.01	16575.5
3047.37	16703.3
3044.73	17008
3042.09	16956
3039.45	16996.8
3036.81	17301.5
3034.16	17640.8
3031.52	17647.8
3028.88	18029.5
3026.23	18560.8
3023.58	18637.8
3020.93	18524.3
3018.29	18699.8
3015.64	19014.3
3012.99	18744.8
3010.33	18503.5
3007.68	18467.5
3005.03	18508.8
3002.37	18141
2999.72	18028
2997.06	18321.3
2994.41	18204.5
2991.75	18009
2989.09	18133
2986.43	18291.5
2983.77	18085.8
2981.11	17956.5
2978.44	18252
2975.78	18346.8
2973.12	18129.5
2970.45	18119.8
2967.78	18301
2965.12	18209
2962.45	17883
2959.78	18120.5
2957.11	18203.3
2954.44	18265.8
2951.77	17900.3
2949.1	18045.8
2946.42	18108.8
2943.75	17909.3
2941.07	17686.8
2938.4	18019
2935.72	17912.5
2933.04	17638.8
2930.36	17678.3
2927.68	17851
2925	17847.5
2922.32	17493
2919.64	17734
2916.95	17968.3
2914.27	17819.5
2911.58	17568
2908.9	17723
2906.21	17916.8
2903.52	17703.8
2900.83	17595
2898.14	17839
2895.45	18098.5
2892.76	17838
2890.07	17624.3
2887.37	17954.8
2884.68	17936.3
2881.98	17902
2879.28	17772.3
2876.59	17999
2873.89	18078.5
2871.19	18007.8
2868.49	17994.8
2865.79	18187.5
2863.09	18295.8
2860.38	18017.8
2857.68	18140.8
2854.97	18247.5
2852.27	18147.5
2849.56	18147.5
2846.85	18247.5
2844.14	18317
2841.43	18212.8
2838.72	18203.5
2836.01	18311.3
2833.3	18408
2830.58	18350.8
2827.87	18123.5
2825.15	18265.8
2822.44	18481.8
2819.72	18283.5
2817	18177.3
2814.28	18420.5
2811.56	18501.8
2808.84	18333.8
2806.12	18228.5
2803.4	18371.5
2800.67	18462.5
2797.95	18337.8
2795.22	18291.5
2792.5	18418.3
2789.77	18594
2787.04	18496
2784.31	18461
2781.58	18551.5
2778.85	18736
2776.12	18592
2773.38	18512.3
2770.65	18591.8
2767.91	18655.8
2765.18	18470.8
2762.44	18379.5
2759.7	18428
2756.96	18734.8
2754.22	18428
2751.48	18372.5
2748.74	18418.8
2745.99	18480
2743.25	18639.5
2740.51	18612.5
2737.76	18553.5
2735.01	18745.5
2732.27	18778.5
2729.52	18654.8
2726.77	18695.3
2724.02	19088.5
2721.27	18979.8
2718.51	18929.8
2715.76	19141.5
2713	19389.8
2710.25	19340.8
2707.49	19242.3
2704.73	19336.8
2701.98	19660.3
2699.22	19674.8
2696.46	19536.3
2693.7	19652
2690.93	20059.3
2688.17	20146.8
2685.41	20012
2682.64	20237.3
2679.87	20679.8
2677.11	21223
2674.34	21557.3
2671.57	21947.3
2668.8	22647.8
2666.03	23172.8
2663.26	23398
2660.48	23475.8
2657.71	23706.3
2654.94	23675.5
2652.16	23392.8
2649.38	22755
2646.61	22373.5
2643.83	22307
2641.05	21874
2638.27	21410.5
2635.49	21226.5
2632.7	21304.5
2629.92	20868.3
2627.13	20648.3
2624.35	20415.8
2621.56	20366.8
2618.77	20292.8
2615.99	19940.5
2613.2	19917
2610.41	19959.3
2607.61	19996.5
2604.82	19811.3
2602.03	19625
2599.23	19676
2596.44	19790.3
2593.64	19712
2590.84	19423.5
2588.05	19358
2585.25	19514.5
2582.45	19490
2579.65	19288.3
2576.84	19083.8
2574.04	19186.5
2571.24	19265.5
2568.43	18987.8
2565.62	18938
2562.82	19060.3
2560.01	19037.3
2557.2	19018.5
2554.39	18879.8
2551.58	18969.3
2548.77	19210
2545.95	19059
2543.14	19018.3
2540.32	19031.5
2537.51	19311.8
2534.69	19506.5
2531.87	19461.5
2529.05	19367.5
2526.23	19904
2523.41	20134.8
2520.59	20287.8
2517.77	20141.5
2514.94	20210.5
2512.12	20391.5
2509.29	20294.3
2506.46	19883.3
2503.63	19697.5
2500.81	19618.3
2497.98	19619
2495.15	19454.8
2492.31	19136.8
2489.48	19170
2486.65	19258
2483.81	19254.3
2480.97	19016.3
2478.14	19049
2475.3	19110.5
2472.46	19167.8
2469.62	19104.3
2466.78	19067.5
2463.94	19213.8
2461.09	19319
2458.25	19332
2455.4	19334.3
2452.56	19253.5
2449.71	19185.5
2446.86	19309.8
2444.01	19364
2441.16	19200.8
2438.31	19273.5
2435.46	19279
2432.6	19555
2429.75	19438.5
2426.89	19354
2424.04	19324
2421.18	19464
2418.32	19648.8
2415.46	19404.5
2412.6	19356
2409.74	19333.3
2406.88	19456.5
2404.01	19405.3
2401.15	19296
2398.28	19063.8
2395.42	19283
2392.55	19424.3
2389.68	19394.5
2386.81	19176
2383.94	19182.8
2381.07	19358.8
2378.2	19462.5
2375.32	19296
2372.45	19213.3
2369.57	19378.5
2366.7	19582.5
2363.82	19571.5
2360.94	19447.5
2358.06	19435.8
2355.18	19490.8
2352.3	19618
2349.41	19576.8
2346.53	19519.3
2343.64	19586.8
2340.76	19771
2337.87	19930
2334.98	19819.3
2332.09	19745
2329.2	19717
2326.31	19910
2323.42	20157.5
2320.53	20261.8
2317.63	20262.5
2314.74	20580
2311.84	21164.3
2308.94	21584.5
2306.04	21868
2303.15	21854.3
2300.24	21744.3
2297.34	21866
2294.44	21755.5
2291.54	21533.5
2288.63	21161.5
2285.72	21087.8
2282.82	21098.8
2279.91	20922.5
2277	20780
2274.09	20679.8
2271.18	20744.8
2268.27	20772.5
2265.36	20851.8
2262.44	20692
2259.53	20546.5
2256.61	20530
2253.69	20579
2250.77	20603
2247.86	20572
2244.93	20380.5
2242.01	20529.5
2239.09	20615.8
2236.17	20677.8
2233.24	20665.5
2230.32	20641.8
2227.39	20527.8
2224.46	20717.3
2221.53	20819.3
2218.6	20856
2215.67	20670.3
2212.74	20612.3
2209.81	20810
2206.87	20854.8
2203.94	20977.8
2201	20865.3
2198.06	20815
2195.13	21038.8
2192.19	21072.8
2189.25	20947.3
2186.3	21091.5
2183.36	21149.8
2180.42	21240.5
2177.47	21371.8
2174.53	21730.3
2171.58	21719.3
2168.63	21878.8
2165.68	21907.5
2162.73	22320.3
2159.78	22496
2156.83	22684.8
2153.88	22471
2150.92	22394.8
2147.97	22430.8
2145.01	22401
2142.05	22130.5
2139.09	22123.5
2136.13	21874.3
2133.17	21933
2130.21	21916.5
2127.25	22003
2124.29	21920.8
2121.32	21862
2118.35	21852.8
2115.39	22011.8
2112.42	22012.3
2109.45	22101.3
2106.48	22005
2103.51	22004.8
2100.54	22124.3
2097.56	22096
2094.59	22208.5
2091.61	22126
2088.64	21948
2085.66	22215.8
2082.68	22020.5
2079.7	22203.5
2076.72	22205
2073.73	22095
2070.75	21983.3
2067.77	22121
2064.78	22074.8
2061.79	22084.3
2058.81	21892
2055.82	22017.8
2052.83	22062.3
2049.84	22122
2046.85	22327
2043.85	22303.8
2040.86	22295.5
2037.86	22320.8
2034.87	22306.8
2031.87	22469.8
2028.87	22608
2025.87	22671.3
2022.87	22523
2019.87	22473.5
2016.86	22775.5
2013.86	22967.5
2010.85	22885.8
2007.85	22781.5
2004.84	22693.8
2001.83	22702
1998.82	22884.5
1995.81	22925
1992.8	22894.5
1989.79	22813.5
1986.78	22877.5
1983.76	22718
1980.74	23081
1977.73	23077
1974.71	23105.8
1971.69	23214
1968.67	23015.5
1965.65	23094
1962.62	23313.3
1959.6	23480.8
1956.57	23683.5
1953.55	23415.5
1950.52	23576.8
1947.49	23598.5
1944.46	23667.8
1941.43	23955.5
1938.4	24035.5
1935.37	23879
1932.34	23987.3
1929.3	24009.8
1926.26	24184.8
1923.23	24273.5
1920.19	24273.5
1917.15	24303
1914.11	24314
1911.07	24281.5
1908.02	24450.5
1904.98	24563.3
1901.94	24643
1898.89	24552
1895.84	24443.5
1892.79	24530
1889.74	24458.3
1886.69	24654.5
1883.64	24808
1880.59	24661.3
1877.54	24606.8
1874.48	24535.5
1871.43	24617
1868.37	24590.5
1865.31	24470.5
1862.25	24696.5
1859.19	24488.5
1856.13	24519.3
1853.06	24619
1850	24477.8
1846.94	24470.5
1843.87	24589.3
1840.8	24612.8
1837.73	24609.3
1834.66	24443.5
1831.59	24556.8
1828.52	24683.5
1825.45	24832.3
1822.37	24672.8
1819.3	24705.8
1816.22	24664
1813.14	24663
1810.06	24760.8
1806.99	25078.8
1803.9	25067.5
1800.82	25064.3
1797.74	24962
1794.65	25131.8
1791.57	25185.3
1788.48	25283.3
1785.39	25283.8
1782.31	25262
1779.21	25202
1776.12	25134.5
1773.03	25270.8
1769.94	25053.5
1766.84	25283.3
1763.75	25269.5
1760.65	25383.3
1757.55	25204.5
1754.45	25044
1751.35	25233.5
1748.25	25213
1745.15	25202.8
1742.05	25048.3
1738.94	25060.5
1735.83	24906.5
1732.73	24811.5
1729.62	24841.8
1726.51	24736.3
1723.4	24605
1720.29	24610.5
1717.17	24560.8
1714.06	24601.5
1710.94	24376
1707.83	24358.5
1704.71	24503.3
1701.59	24591.5
1698.47	24505.5
1695.35	24273
1692.23	24349.5
1689.1	24177.3
1685.98	24108.3
1682.85	24268.3
1679.73	24380.3
1676.6	24201
1673.47	24288.5
1670.34	24244.8
1667.21	24308.5
1664.07	24432
1660.94	24373
1657.81	24536.5
1654.67	24615
1651.53	24625.5
1648.39	24650.3
1645.25	24622.8
1642.11	24724.5
1638.97	24658.3
1635.83	24607.3
1632.68	24630.3
1629.54	24649.5
1626.39	24550.5
1623.24	24323.5
1620.09	24455.5
1616.94	24360
1613.79	24469.8
1610.64	24459.8
1607.48	24476.5
1604.33	24680.5
1601.17	24408
1598.02	24372
1594.86	24315
1591.7	24422.3
1588.54	24537
1585.38	24542.5
1582.21	24660
1579.05	24798
1575.88	24581.5
1572.72	24736.5
1569.55	24603.8
1566.38	24576.3
1563.21	24719.3
1560.04	24568.8
1556.86	24541.5
1553.69	24314.8
1550.51	24426.5
1547.34	24359.5
1544.16	24443.3
1540.98	24584
1537.8	24639
1534.62	24794.3
1531.44	25336.5
1528.26	26226
1525.07	27707.5
1521.89	30597.5
1518.7	34507.3
1515.51	38687.3
1512.32	42277.5
1509.13	44677.5
1505.94	44344.5
1502.75	40861.5
1499.55	35746.3
1496.36	31483.5
1493.16	28524
1489.96	26607.5
1486.76	25403.3
1483.56	24738.5
1480.36	24029.8
1477.16	23534
1473.96	23146.5
1470.75	22598.5
1467.54	22332.5
1464.34	22251.8
1461.13	22168.3
1457.92	22091.5
1454.71	21986
1451.49	22045
1448.28	21848.3
1445.07	21885.8
1441.85	21954.5
1438.63	21853.3
1435.41	21657.5
1432.2	21458
1428.98	21103.8
1425.75	21123.8
1422.53	20971.3
1419.31	20711.8
1416.08	20577.5
1412.85	20488.5
1409.63	20343.5
1406.4	20309.5
1403.17	20247.3
1399.93	20261.3
1396.7	20230.3
1393.47	20377.5
1390.23	20253.3
1387	20252
1383.76	19951.5
1380.52	19741
1377.28	19605.8
1374.04	19535
1370.8	19413.5
1367.55	19272.8
1364.31	19100.8
1361.06	19009.5
1357.81	18821.8
1354.56	18687.3
1351.31	18617.3
1348.06	18561.8
1344.81	18387
1341.56	18233.5
1338.3	18075
1335.04	17834
1331.79	17828.3
1328.53	17648.3
1325.27	17463.5
1322.01	17366.5
1318.75	17188.8
1315.48	17247.3
1312.22	17312
1308.95	17376
1305.68	17199.3
1302.41	17234.3
1299.15	17175.5
1295.88	17185.3
1292.6	16947
1289.33	16933
1286.06	16746.5
1282.78	16842
1279.5	16849.8
1276.22	16989.8
1272.94	17178.5
1269.66	17290.8
1266.38	17332.5
1263.1	17466.8
1259.81	17239.8
1256.53	16698.8
1253.24	16423
1249.95	16144.8
1246.66	16066.3
1243.37	15902.3
1240.08	15761
1236.78	15691.8
1233.49	15697.5
1230.19	15612.8
1226.9	15624
1223.6	15627
1220.3	15729.8
1217	15688.3
1213.69	16027.5
1210.39	16387.5
1207.09	16948.8
1203.78	17157.5
1200.47	16801.3
1197.16	16311.8
1193.86	16348.5
1190.54	16711.8
1187.23	17221.3
1183.92	17658.3
1180.6	17373.5
1177.29	16759.3
1173.97	16506
1170.65	16577.8
1167.33	16942
1164.01	17611.8
1160.69	19119
1157.36	22101.8
1154.04	26998.5
1150.71	31182.5
1147.38	30639.3
1144.06	25864
1140.73	21743.8
1137.4	18760.5
1134.06	17158.3
1130.73	16053.8
1127.39	15074.5
1124.06	14680.5
1120.72	14299.8
1117.38	13976
1114.04	13551
1110.7	13235.3
1107.35	13021.5
1104.01	12571
1100.67	12521.8
1097.32	12305.5
1093.97	12137.3
1090.62	11930.3
1087.27	11833.5
1083.92	11661.5
1080.57	11617.8
1077.21	11562.8
1073.86	11433.5
1070.5	11370.3
1067.14	11211
1063.78	11223
1060.42	11123.5
1057.06	11130.3
1053.69	11069.5
1050.33	11073
1046.96	10997.5
1043.6	10969.3
1040.23	11025.5
1036.86	10993.3
1033.49	10918
1030.11	11067.3
1026.74	11153.5
1023.36	11346.8
1019.99	11685.5
1016.61	11984.5
1013.23	12532.8
1009.85	13036.5
1006.47	13467.5
1003.09	14044.3
999.701	13853.5
996.315	13074.8
992.929	12035.3
989.54	11192.3
986.152	10722
982.76	10216.3
979.368	10039.8
975.976	9878.5
972.58	9606
969.183	9371
965.787	9312
962.388	9161.75
958.988	9074
955.588	8977
952.185	8800
948.78	8680.75
945.374	8595.5
941.969	8587
938.561	8484.75
935.151	8314.25
931.74	8351
928.33	8253
924.916	8235.25
921.501	8192.75
918.085	8214.75
914.668	8112
911.251	7993.5
907.831	8012.75
904.409	8040
900.987	8005.25
897.563	7939.5
894.137	7882.75
890.713	7895.75
887.285	7885.75
883.855	7806.5
880.425	7820
876.993	7780
873.56	7809
870.125	7861.25
866.689	7935
863.252	7905.75
859.813	7891.5
856.374	7707.75
852.933	7617
849.49	7454
846.046	7417
842.601	7293.25
839.155	7176.25
835.707	7183
832.258	7090.5
828.808	7082.5
825.356	7024.25
821.903	7066.5
818.448	6904.5
814.993	6943.25
811.536	6906
808.077	6908.75
804.618	6829.75
801.157	6829
797.694	6823
794.229	6764
790.764	6859
787.297	6813
783.83	6790
780.361	6737.75
776.89	6708.5
773.419	6666.5
769.943	6705
766.469	6640
762.993	6590
759.516	6573.5
756.038	6556
752.556	6535.75
749.075	6497.5
745.593	6452.25
742.109	6366.5
738.622	6351
735.135	6325.75
731.648	6220.25
728.156	6168.5
724.666	6224.75
721.174	6133
717.681	6138.75
714.184	6123
710.688	5982.5
707.191	5925.5
703.69	5989
700.191	5933.5
696.687	5792.25
693.185	5882.25
689.68	5760.5
686.173	5723.25
682.666	5750.25
679.158	5736.75
675.647	5630.5
672.136	5705.75
668.622	5636.75
665.108	5645.25
661.591	5676.25
658.075	5635.5
654.555	5587.75
651.036	5634.25
647.514	5607.5
643.992	5621.75
640.467	5607.25
636.943	5588.5
633.415	5571
629.888	5530.75
626.357	5502.75
622.827	5559.5
619.294	5418
615.761	5441.75
612.225	5456.5
608.689	5399.5
605.151	5372.5
601.61	5353.25
598.071	5347
594.528	5298.25
590.983	5298.5
587.44	5189.25
583.892	5210.5
580.346	5181.75
576.796	5161.25
573.245	5127.25
569.694	5072
566.14	5023.25
562.585	5072
559.03	5034.5
555.472	4987.25
551.912	4960.5
548.351	5026.75
544.791	5010
541.227	4982.75
537.662	4933.25
534.095	4909
530.529	4895.25
526.96	4894.5
523.389	4875
519.817	4867
516.244	4828.5
512.671	4829
509.094	4795.5
505.517	4761.25
501.938	4721.75
498.357	4648.5
494.775	4685.5
491.194	4646.5
487.609	4650.5
484.023	4615.5
480.435	4627.5
476.847	4603.25
473.256	4620.25
469.664	4579.5
466.071	4548.75
462.477	4517.25
458.883	4386
455.285	4412.25
451.686	4431.5
448.086	4371.75
444.485	4452.75
440.882	4333.75
437.277	4349.25
433.671	4292.75
430.064	4255.75
426.455	4307.75
422.845	4211
419.233	4205.5
415.621	4142.75
412.006	4133.5
408.39	4125.5
404.773	4054.75
401.154	4030.5
397.532	3957.5
393.911	3951
390.288	3925.5
386.663	3909.25
383.038	3905.25
379.41	3835
375.782	3864.25
372.152	3774.5
368.52	3824.25
364.885	3842
361.251	3835.5
357.615	3798.25
353.978	3746.5
350.339	3751.5
346.699	3721.25
343.055	3669
339.412	3689.5
335.768	3664.5
332.122	3623.25
328.474	3581.5
324.824	3569.5
321.173	3507.5
317.522	3533.25
313.869	3524.75
310.212	3496.75
306.556	3443.75
302.899	3378.5
299.238	3393.75
295.577	3389.75
291.916	3377
288.252	3437.75
284.586	3367
280.919	3372.75
277.252	3364
273.581	3310.75
269.91	3303.75
266.236	3287.5
262.563	3209.75
258.888	3210.5
255.21	3223.25
251.532	3170.75
247.852	3122
244.17	3141.25
240.488	3134.75
236.802	3090.5
233.117	3078
229.428	3033.25
225.74	3019
222.051	3010.75
218.358	2938
214.665	2928.25
210.969	2931.5
207.274	2871.75
203.575	2810.5
199.877	2805.5
196.175	2780.75
192.473	2798.5
188.769	2777.5
185.064	2737
181.357	2709
177.647	2751
173.939	2680
170.227	2631
166.515	2686
162.8	2636.75
159.085	2669
155.367	2667.5
151.647	2615.75
147.928	2686
144.206	2638.25
140.482	2613
136.758	2591
133.031	2627.75
129.305	2613.75
125.575	2539.75
121.843	2549.25
118.112	2453.5
114.378	2434.25